| test.py:127:9:127:26 | ValueError() | Instantiating an exception, but not raising it, has no effect. |
